Workbook

Sheet Data
A1: 5.1 | B1: 3.5 | C1: 1.4 | D1: 0.2 | E1: Iris-setosa
A2: 4.9 | B2: 3 | C2: 1.4 | D2: 0.2 | E2: Iris-setosa
A3: 4.7 | B3: 3.2 | C3: 1.3 | D3: 0.2 | E3: Iris-setosa
A4: 4.6 | B4: 3.1 | C4: 1.5 | D4: 0.2 | E4: Iris-setosa
A5: 5 | B5: 3.6 | C5: 1.4 | D5: 0.2 | E5: Iris-setosa
A6: 5.4 | B6: 3.9 | C6: 1.7 | D6: 0.4 | E6: Iris-setosa
A7: 4.6 | B7: 3.4 | C7: 1.4 | D7: 0.3 | E7: Iris-setosa
A8: 5 | B8: 3.4 | C8: 1.5 | D8: 0.2 | E8: Iris-setosa
A9: 4.4 | B9: 2.9 | C9: 1.4 | D9: 0.2 | E9: Iris-setosa
A10: 4.9 | B10: 3.1 | C10: 1.5 | D10: 0.1 | E10: Iris-setosa
A11: 5.4 | B11: 3.7 | C11: 1.5 | D11: 0.2 | E11: Iris-setosa
A12: 4.8 | B12: 3.4 | C12: 1.6 | D12: 0.2 | E12: Iris-setosa
... A100: 5.7 | B100: 2.8 | C100: 4.1 | D100: 1.3 | E100: Iris-versicolor

Sheet SLP-Training
G2: Setosa = 0 | I2: Learning Rate | K2: 0.1
G3: Versicolor = 1 | I3: Bobot bias | N3: dot product | O3: Sigmoid | P3: Prediksi | Q3: error | R3: Sum Square Error | S3: Benar? | Z3: REKAP TRAINING PER EPOCH
A4: EPOCH | B4: No | C4: X1 | D4: X2 | E4: X3 | F4: X4 | G4: TARGET | I4: bias | J4: teta1 | K4: teta2 | L4: teta 3 | M4: teta4 | N4: z | O4: g(z) | S4: benar | T4: dbias | U4: dteta1 | V4: dteta2 | W4: dteta3 | X4: dteta4 | Z4: Epoch | AA4: Loss (MSE) | AB4: Accuracy | AC4: bias* | AD4: teta1* | AE4: teta2* | AF4: teta3* | AG4: teta4*
A5: epoch 1 | B5: 1 | C5: 5.1 | D5: 3.5 | E5: 1.4 | F5: 0.2 | G5: 0 | I5: 0.5 | J5: 0.5 | K5: 0.5 | L5: 0.5 | M5: 0.5 | N5: =I5+J5*C5+K5*D5+L5*E5+F5*M5 | O5: =1/(1+EXP(-N5)) | P5: =IF(O5>0.5,1,0) | Q5: =O5-G5 | R5: =Q5^2 | S5: =IF(P5=G5,1,0) | T5: =2*(O5-G5)*(1-O5)*O5 | U5: =2*(O5-G5)*(1-O5)*O5*C5 | V5: =2*(O5-G5)*(1-O5)*O5*D5 | W5: =2*(O5-G5)*(1-O5)*O5*E5 | X5: =2*(O5-G5)*(1-O5)*O5*F5 | Z5: 1 | AA5: =AVERAGE(R5:R84) | AB5: =AVERAGE(S5:S84) | AC5: =I84-$K$2*T84 | AD5: =J84-$K$2*U84 | AE5: =K84-$K$2*V84 | AF5: =L84-$K$2*W84 | AG5: =M84-$K$2*X84
B6: 2 | C6: 4.9 | D6: 3 | E6: 1.4 | F6: 0.2 | G6: 0 | I6: =I5-$K$2*T5 | J6: =J5-$K$2*U5 | K6: =K5-$K$2*V5 | L6: =L5-$K$2*W5 | M6: =M5-$K$2*X5 | N6: =I6+J6*C6+K6*D6+L6*E6+F6*M6 | O6: =1/(1+EXP(-N6)) | P6: =IF(O6>0.5,1,0) | Q6: =O6-G6 | R6: =Q6^2 | S6: =IF(P6=G6,1,0) | T6: =2*(O6-G6)*(1-O6)*O6 | U6: =2*(O6-G6)*(1-O6)*O6*C6 | V6: =2*(O6-G6)*(1-O6)*O6*D6 | W6: =2*(O6-G6)*(1-O6)*O6*E6 | X6: =2*(O6-G6)*(1-O6)*O6*F6 | Z6: 2 | AA6: =AVERAGE(R85:R164) | AB6: =AVERAGE(S85:S164) | AC6: =I164-$K$2*T164 | AD6: =J164-$K$2*U164 | AE6: =K164-$K$2*V164 | AF6: =L164-$K$2*W164 | AG6: =M164-$K$2*X164
B7: 3 | C7: 4.7 | D7: 3.2 | E7: 1.3 | F7: 0.2 | G7: 0 | I7: =I6-$K$2*T6 | J7: =J6-$K$2*U6 | K7: =K6-$K$2*V6 | L7: =L6-$K$2*W6 | M7: =M6-$K$2*X6 | N7: =I7+J7*C7+K7*D7+L7*E7+F7*M7 | O7: =1/(1+EXP(-N7)) | P7: =IF(O7>0.5,1,0) | Q7: =O7-G7 | R7: =Q7^2 | S7: =IF(P7=G7,1,0) | T7: =2*(O7-G7)*(1-O7)*O7 | U7: =2*(O7-G7)*(1-O7)*O7*C7 | V7: =2*(O7-G7)*(1-O7)*O7*D7 | W7: =2*(O7-G7)*(1-O7)*O7*E7 | X7: =2*(O7-G7)*(1-O7)*O7*F7 | Z7: 3 | AA7: =AVERAGE(R165:R244) | AB7: =AVERAGE(S165:S244) | AC7: =I244-$K$2*T244 | AD7: =J244-$K$2*U244 | AE7: =K244-$K$2*V244 | AF7: =L244-$K$2*W244 | AG7: =M244-$K$2*X244
B8: 4 | C8: 4.6 | D8: 3.1 | E8: 1.5 | F8: 0.2 | G8: 0 | I8: =I7-$K$2*T7 | J8: =J7-$K$2*U7 | K8: =K7-$K$2*V7 | L8: =L7-$K$2*W7 | M8: =M7-$K$2*X7 | N8: =I8+J8*C8+K8*D8+L8*E8+F8*M8 | O8: =1/(1+EXP(-N8)) | P8: =IF(O8>0.5,1,0) | Q8: =O8-G8 | R8: =Q8^2 | S8: =IF(P8=G8,1,0) | T8: =2*(O8-G8)*(1-O8)*O8 | U8: =2*(O8-G8)*(1-O8)*O8*C8 | V8: =2*(O8-G8)*(1-O8)*O8*D8 | W8: =2*(O8-G8)*(1-O8)*O8*E8 | X8: =2*(O8-G8)*(1-O8)*O8*F8 | Z8: 4 | AA8: =AVERAGE(R245:R324) | AB8: =AVERAGE(S245:S324) | AC8: =I324-$K$2*T324 | AD8: =J324-$K$2*U324 | AE8: =K324-$K$2*V324 | AF8: =L324-$K$2*W324 | AG8: =M324-$K$2*X324
B9: 5 | C9: 5 | D9: 3.6 | E9: 1.4 | F9: 0.2 | G9: 0 | I9: =I8-$K$2*T8 | J9: =J8-$K$2*U8 | K9: =K8-$K$2*V8 | L9: =L8-$K$2*W8 | M9: =M8-$K$2*X8 | N9: =I9+J9*C9+K9*D9+L9*E9+F9*M9 | O9: =1/(1+EXP(-N9)) | P9: =IF(O9>0.5,1,0) | Q9: =O9-G9 | R9: =Q9^2 | S9: =IF(P9=G9,1,0) | T9: =2*(O9-G9)*(1-O9)*O9 | U9: =2*(O9-G9)*(1-O9)*O9*C9 | V9: =2*(O9-G9)*(1-O9)*O9*D9 | W9: =2*(O9-G9)*(1-O9)*O9*E9 | X9: =2*(O9-G9)*(1-O9)*O9*F9 | Z9: 5 | AA9: =AVERAGE(R325:R404) | AB9: =AVERAGE(S325:S404) | AC9: =I404-$K$2*T404 | AD9: =J404-$K$2*U404 | AE9: =K404-$K$2*V404 | AF9: =L404-$K$2*W404 | AG9: =M404-$K$2*X404
B10: 6 | C10: 5.4 | D10: 3.9 | E10: 1.7 | F10: 0.4 | G10: 0 | I10: =I9-$K$2*T9 | J10: =J9-$K$2*U9 | K10: =K9-$K$2*V9 | L10: =L9-$K$2*W9 | M10: =M9-$K$2*X9 | N10: =I10+J10*C10+K10*D10+L10*E10+F10*M10 | O10: =1/(1+EXP(-N10)) | P10: =IF(O10>0.5,1,0) | Q10: =O10-G10 | R10: =Q10^2 | S10: =IF(P10=G10,1,0) | T10: =2*(O10-G10)*(1-O10)*O10 | U10: =2*(O10-G10)*(1-O10)*O10*C10 | V10: =2*(O10-G10)*(1-O10)*O10*D10 | W10: =2*(O10-G10)*(1-O10)*O10*E10 | X10: =2*(O10-G10)*(1-O10)*O10*F10
B11: 7 | C11: 4.6 | D11: 3.4 | E11: 1.4 | F11: 0.3 | G11: 0 | I11: =I10-$K$2*T10 | J11: =J10-$K$2*U10 | K11: =K10-$K$2*V10 | L11: =L10-$K$2*W10 | M11: =M10-$K$2*X10 | N11: =I11+J11*C11+K11*D11+L11*E11+F11*M11 | O11: =1/(1+EXP(-N11)) | P11: =IF(O11>0.5,1,0) | Q11: =O11-G11 | R11: =Q11^2 | S11: =IF(P11=G11,1,0) | T11: =2*(O11-G11)*(1-O11)*O11 | U11: =2*(O11-G11)*(1-O11)*O11*C11 | V11: =2*(O11-G11)*(1-O11)*O11*D11 | W11: =2*(O11-G11)*(1-O11)*O11*E11 | X11: =2*(O11-G11)*(1-O11)*O11*F11 | Z11: * bobot pada akhir epoch, dipakai oleh sheet SLP-Validation
B12: 8 | C12: 5 | D12: 3.4 | E12: 1.5 | F12: 0.2 | G12: 0 | I12: =I11-$K$2*T11 | J12: =J11-$K$2*U11 | K12: =K11-$K$2*V11 | L12: =L11-$K$2*W11 | M12: =M11-$K$2*X11 | N12: =I12+J12*C12+K12*D12+L12*E12+F12*M12 | O12: =1/(1+EXP(-N12)) | P12: =IF(O12>0.5,1,0) | Q12: =O12-G12 | R12: =Q12^2 | S12: =IF(P12=G12,1,0) | T12: =2*(O12-G12)*(1-O12)*O12 | U12: =2*(O12-G12)*(1-O12)*O12*C12 | V12: =2*(O12-G12)*(1-O12)*O12*D12 | W12: =2*(O12-G12)*(1-O12)*O12*E12 | X12: =2*(O12-G12)*(1-O12)*O12*F12
B13: 9 | C13: 4.4 | D13: 2.9 | E13: 1.4 | F13: 0.2 | G13: 0 | I13: =I12-$K$2*T12 | J13: =J12-$K$2*U12 | K13: =K12-$K$2*V12 | L13: =L12-$K$2*W12 | M13: =M12-$K$2*X12 | N13: =I13+J13*C13+K13*D13+L13*E13+F13*M13 | O13: =1/(1+EXP(-N13)) | P13: =IF(O13>0.5,1,0) | Q13: =O13-G13 | R13: =Q13^2 | S13: =IF(P13=G13,1,0) | T13: =2*(O13-G13)*(1-O13)*O13 | U13: =2*(O13-G13)*(1-O13)*O13*C13 | V13: =2*(O13-G13)*(1-O13)*O13*D13 | W13: =2*(O13-G13)*(1-O13)*O13*E13 | X13: =2*(O13-G13)*(1-O13)*O13*F13
B14: 10 | C14: 4.9 | D14: 3.1 | E14: 1.5 | F14: 0.1 | G14: 0 | I14: =I13-$K$2*T13 | J14: =J13-$K$2*U13 | K14: =K13-$K$2*V13 | L14: =L13-$K$2*W13 | M14: =M13-$K$2*X13 | N14: =I14+J14*C14+K14*D14+L14*E14+F14*M14 | O14: =1/(1+EXP(-N14)) | P14: =IF(O14>0.5,1,0) | Q14: =O14-G14 | R14: =Q14^2 | S14: =IF(P14=G14,1,0) | T14: =2*(O14-G14)*(1-O14)*O14 | U14: =2*(O14-G14)*(1-O14)*O14*C14 | V14: =2*(O14-G14)*(1-O14)*O14*D14 | W14: =2*(O14-G14)*(1-O14)*O14*E14 | X14: =2*(O14-G14)*(1-O14)*O14*F14
B15: 11 | C15: 5.4 | D15: 3.7 | E15: 1.5 | F15: 0.2 | G15: 0 | I15: =I14-$K$2*T14 | J15: =J14-$K$2*U14 | K15: =K14-$K$2*V14 | L15: =L14-$K$2*W14 | M15: =M14-$K$2*X14 | N15: =I15+J15*C15+K15*D15+L15*E15+F15*M15 | O15: =1/(1+EXP(-N15)) | P15: =IF(O15>0.5,1,0) | Q15: =O15-G15 | R15: =Q15^2 | S15: =IF(P15=G15,1,0) | T15: =2*(O15-G15)*(1-O15)*O15 | U15: =2*(O15-G15)*(1-O15)*O15*C15 | V15: =2*(O15-G15)*(1-O15)*O15*D15 | W15: =2*(O15-G15)*(1-O15)*O15*E15 | X15: =2*(O15-G15)*(1-O15)*O15*F15
B16: 12 | C16: 4.8 | D16: 3.4 | E16: 1.6 | F16: 0.2 | G16: 0 | I16: =I15-$K$2*T15 | J16: =J15-$K$2*U15 | K16: =K15-$K$2*V15 | L16: =L15-$K$2*W15 | M16: =M15-$K$2*X15 | N16: =I16+J16*C16+K16*D16+L16*E16+F16*M16 | O16: =1/(1+EXP(-N16)) | P16: =IF(O16>0.5,1,0) | Q16: =O16-G16 | R16: =Q16^2 | S16: =IF(P16=G16,1,0) | T16: =2*(O16-G16)*(1-O16)*O16 | U16: =2*(O16-G16)*(1-O16)*O16*C16 | V16: =2*(O16-G16)*(1-O16)*O16*D16 | W16: =2*(O16-G16)*(1-O16)*O16*E16 | X16: =2*(O16-G16)*(1-O16)*O16*F16
B17: 13 | C17: 4.8 | D17: 3 | E17: 1.4 | F17: 0.1 | G17: 0 | I17: =I16-$K$2*T16 | J17: =J16-$K$2*U16 | K17: =K16-$K$2*V16 | L17: =L16-$K$2*W16 | M17: =M16-$K$2*X16 | N17: =I17+J17*C17+K17*D17+L17*E17+F17*M17 | O17: =1/(1+EXP(-N17)) | P17: =IF(O17>0.5,1,0) | Q17: =O17-G17 | R17: =Q17^2 | S17: =IF(P17=G17,1,0) | T17: =2*(O17-G17)*(1-O17)*O17 | U17: =2*(O17-G17)*(1-O17)*O17*C17 | V17: =2*(O17-G17)*(1-O17)*O17*D17 | W17: =2*(O17-G17)*(1-O17)*O17*E17 | X17: =2*(O17-G17)*(1-O17)*O17*F17
B18: 14 | C18: 4.3 | D18: 3 | E18: 1.1 | F18: 0.1 | G18: 0 | I18: =I17-$K$2*T17 | J18: =J17-$K$2*U17 | K18: =K17-$K$2*V17 | L18: =L17-$K$2*W17 | M18: =M17-$K$2*X17 | N18: =I18+J18*C18+K18*D18+L18*E18+F18*M18 | O18: =1/(1+EXP(-N18)) | P18: =IF(O18>0.5,1,0) | Q18: =O18-G18 | R18: =Q18^2 | S18: =IF(P18=G18,1,0) | T18: =2*(O18-G18)*(1-O18)*O18 | U18: =2*(O18-G18)*(1-O18)*O18*C18 | V18: =2*(O18-G18)*(1-O18)*O18*D18 | W18: =2*(O18-G18)*(1-O18)*O18*E18 | X18: =2*(O18-G18)*(1-O18)*O18*F18
B19: 15 | C19: 5.8 | D19: 4 | E19: 1.2 | F19: 0.2 | G19: 0 | I19: =I18-$K$2*T18 | J19: =J18-$K$2*U18 | K19: =K18-$K$2*V18 | L19: =L18-$K$2*W18 | M19: =M18-$K$2*X18 | N19: =I19+J19*C19+K19*D19+L19*E19+F19*M19 | O19: =1/(1+EXP(-N19)) | P19: =IF(O19>0.5,1,0) | Q19: =O19-G19 | R19: =Q19^2 | S19: =IF(P19=G19,1,0) | T19: =2*(O19-G19)*(1-O19)*O19 | U19: =2*(O19-G19)*(1-O19)*O19*C19 | V19: =2*(O19-G19)*(1-O19)*O19*D19 | W19: =2*(O19-G19)*(1-O19)*O19*E19 | X19: =2*(O19-G19)*(1-O19)*O19*F19
B20: 16 | C20: 5.7 | D20: 4.4 | E20: 1.5 | F20: 0.4 | G20: 0 | I20: =I19-$K$2*T19 | J20: =J19-$K$2*U19 | K20: =K19-$K$2*V19 | L20: =L19-$K$2*W19 | M20: =M19-$K$2*X19 | N20: =I20+J20*C20+K20*D20+L20*E20+F20*M20 | O20: =1/(1+EXP(-N20)) | P20: =IF(O20>0.5,1,0) | Q20: =O20-G20 | R20: =Q20^2 | S20: =IF(P20=G20,1,0) | T20: =2*(O20-G20)*(1-O20)*O20 | U20: =2*(O20-G20)*(1-O20)*O20*C20 | V20: =2*(O20-G20)*(1-O20)*O20*D20 | W20: =2*(O20-G20)*(1-O20)*O20*E20 | X20: =2*(O20-G20)*(1-O20)*O20*F20
B21: 17 | C21: 5.4 | D21: 3.9 | E21: 1.3 | F21: 0.4 | G21: 0 | I21: =I20-$K$2*T20 | J21: =J20-$K$2*U20 | K21: =K20-$K$2*V20 | L21: =L20-$K$2*W20 | M21: =M20-$K$2*X20 | N21: =I21+J21*C21+K21*D21+L21*E21+F21*M21 | O21: =1/(1+EXP(-N21)) | P21: =IF(O21>0.5,1,0) | Q21: =O21-G21 | R21: =Q21^2 | S21: =IF(P21=G21,1,0) | T21: =2*(O21-G21)*(1-O21)*O21 | U21: =2*(O21-G21)*(1-O21)*O21*C21 | V21: =2*(O21-G21)*(1-O21)*O21*D21 | W21: =2*(O21-G21)*(1-O21)*O21*E21 | X21: =2*(O21-G21)*(1-O21)*O21*F21
B22: 18 | C22: 5.1 | D22: 3.5 | E22: 1.4 | F22: 0.3 | G22: 0 | I22: =I21-$K$2*T21 | J22: =J21-$K$2*U21 | K22: =K21-$K$2*V21 | L22: =L21-$K$2*W21 | M22: =M21-$K$2*X21 | N22: =I22+J22*C22+K22*D22+L22*E22+F22*M22 | O22: =1/(1+EXP(-N22)) | P22: =IF(O22>0.5,1,0) | Q22: =O22-G22 | R22: =Q22^2 | S22: =IF(P22=G22,1,0) | T22: =2*(O22-G22)*(1-O22)*O22 | U22: =2*(O22-G22)*(1-O22)*O22*C22 | V22: =2*(O22-G22)*(1-O22)*O22*D22 | W22: =2*(O22-G22)*(1-O22)*O22*E22 | X22: =2*(O22-G22)*(1-O22)*O22*F22
B23: 19 | C23: 5.7 | D23: 3.8 | E23: 1.7 | F23: 0.3 | G23: 0 | I23: =I22-$K$2*T22 | J23: =J22-$K$2*U22 | K23: =K22-$K$2*V22 | L23: =L22-$K$2*W22 | M23: =M22-$K$2*X22 | N23: =I23+J23*C23+K23*D23+L23*E23+F23*M23 | O23: =1/(1+EXP(-N23)) | P23: =IF(O23>0.5,1,0) | Q23: =O23-G23 | R23: =Q23^2 | S23: =IF(P23=G23,1,0) | T23: =2*(O23-G23)*(1-O23)*O23 | U23: =2*(O23-G23)*(1-O23)*O23*C23 | V23: =2*(O23-G23)*(1-O23)*O23*D23 | W23: =2*(O23-G23)*(1-O23)*O23*E23 | X23: =2*(O23-G23)*(1-O23)*O23*F23
... B84: 80 | C84: 5.5 | D84: 2.5 | E84: 4 | F84: 1.3 | G84: 1 | I84: =I83-$K$2*T83 | J84: =J83-$K$2*U83 | K84: =K83-$K$2*V83 | L84: =L83-$K$2*W83 | M84: =M83-$K$2*X83 | N84: =I84+J84*C84+K84*D84+L84*E84+F84*M84 | O84: =1/(1+EXP(-N84)) | P84: =IF(O84>0.5,1,0) | Q84: =O84-G84 | R84: =Q84^2 | S84: =IF(P84=G84,1,0) | T84: =2*(O84-G84)*(1-O84)*O84 | U84: =2*(O84-G84)*(1-O84)*O84*C84 | V84: =2*(O84-G84)*(1-O84)*O84*D84 | W84: =2*(O84-G84)*(1-O84)*O84*E84 | X84: =2*(O84-G84)*(1-O84)*O84*F84
A85: epoch 2 | B85: 1 | C85: 5.1 | D85: 3.5 | E85: 1.4 | F85: 0.2 | G85: 0 | I85: =I84-$K$2*T84 | J85: =J84-$K$2*U84 | K85: =K84-$K$2*V84 | L85: =L84-$K$2*W84 | M85: =M84-$K$2*X84 | N85: =I85+J85*C85+K85*D85+L85*E85+F85*M85 | O85: =1/(1+EXP(-N85)) | P85: =IF(O85>0.5,1,0) | Q85: =O85-G85 | R85: =Q85^2 | S85: =IF(P85=G85,1,0) | T85: =2*(O85-G85)*(1-O85)*O85 | U85: =2*(O85-G85)*(1-O85)*O85*C85 | V85: =2*(O85-G85)*(1-O85)*O85*D85 | W85: =2*(O85-G85)*(1-O85)*O85*E85 | X85: =2*(O85-G85)*(1-O85)*O85*F85
B86: 2 | C86: 4.9 | D86: 3 | E86: 1.4 | F86: 0.2 | G86: 0 | I86: =I85-$K$2*T85 | J86: =J85-$K$2*U85 | K86: =K85-$K$2*V85 | L86: =L85-$K$2*W85 | M86: =M85-$K$2*X85 | N86: =I86+J86*C86+K86*D86+L86*E86+F86*M86 | O86: =1/(1+EXP(-N86)) | P86: =IF(O86>0.5,1,0) | Q86: =O86-G86 | R86: =Q86^2 | S86: =IF(P86=G86,1,0) | T86: =2*(O86-G86)*(1-O86)*O86 | U86: =2*(O86-G86)*(1-O86)*O86*C86 | V86: =2*(O86-G86)*(1-O86)*O86*D86 | W86: =2*(O86-G86)*(1-O86)*O86*E86 | X86: =2*(O86-G86)*(1-O86)*O86*F86
B87: 3 | C87: 4.7 | D87: 3.2 | E87: 1.3 | F87: 0.2 | G87: 0 | I87: =I86-$K$2*T86 | J87: =J86-$K$2*U86 | K87: =K86-$K$2*V86 | L87: =L86-$K$2*W86 | M87: =M86-$K$2*X86 | N87: =I87+J87*C87+K87*D87+L87*E87+F87*M87 | O87: =1/(1+EXP(-N87)) | P87: =IF(O87>0.5,1,0) | Q87: =O87-G87 | R87: =Q87^2 | S87: =IF(P87=G87,1,0) | T87: =2*(O87-G87)*(1-O87)*O87 | U87: =2*(O87-G87)*(1-O87)*O87*C87 | V87: =2*(O87-G87)*(1-O87)*O87*D87 | W87: =2*(O87-G87)*(1-O87)*O87*E87 | X87: =2*(O87-G87)*(1-O87)*O87*F87
B88: 4 | C88: 4.6 | D88: 3.1 | E88: 1.5 | F88: 0.2 | G88: 0 | I88: =I87-$K$2*T87 | J88: =J87-$K$2*U87 | K88: =K87-$K$2*V87 | L88: =L87-$K$2*W87 | M88: =M87-$K$2*X87 | N88: =I88+J88*C88+K88*D88+L88*E88+F88*M88 | O88: =1/(1+EXP(-N88)) | P88: =IF(O88>0.5,1,0) | Q88: =O88-G88 | R88: =Q88^2 | S88: =IF(P88=G88,1,0) | T88: =2*(O88-G88)*(1-O88)*O88 | U88: =2*(O88-G88)*(1-O88)*O88*C88 | V88: =2*(O88-G88)*(1-O88)*O88*D88 | W88: =2*(O88-G88)*(1-O88)*O88*E88 | X88: =2*(O88-G88)*(1-O88)*O88*F88
B89: 5 | C89: 5 | D89: 3.6 | E89: 1.4 | F89: 0.2 | G89: 0 | I89: =I88-$K$2*T88 | J89: =J88-$K$2*U88 | K89: =K88-$K$2*V88 | L89: =L88-$K$2*W88 | M89: =M88-$K$2*X88 | N89: =I89+J89*C89+K89*D89+L89*E89+F89*M89 | O89: =1/(1+EXP(-N89)) | P89: =IF(O89>0.5,1,0) | Q89: =O89-G89 | R89: =Q89^2 | S89: =IF(P89=G89,1,0) | T89: =2*(O89-G89)*(1-O89)*O89 | U89: =2*(O89-G89)*(1-O89)*O89*C89 | V89: =2*(O89-G89)*(1-O89)*O89*D89 | W89: =2*(O89-G89)*(1-O89)*O89*E89 | X89: =2*(O89-G89)*(1-O89)*O89*F89
B90: 6 | C90: 5.4 | D90: 3.9 | E90: 1.7 | F90: 0.4 | G90: 0 | I90: =I89-$K$2*T89 | J90: =J89-$K$2*U89 | K90: =K89-$K$2*V89 | L90: =L89-$K$2*W89 | M90: =M89-$K$2*X89 | N90: =I90+J90*C90+K90*D90+L90*E90+F90*M90 | O90: =1/(1+EXP(-N90)) | P90: =IF(O90>0.5,1,0) | Q90: =O90-G90 | R90: =Q90^2 | S90: =IF(P90=G90,1,0) | T90: =2*(O90-G90)*(1-O90)*O90 | U90: =2*(O90-G90)*(1-O90)*O90*C90 | V90: =2*(O90-G90)*(1-O90)*O90*D90 | W90: =2*(O90-G90)*(1-O90)*O90*E90 | X90: =2*(O90-G90)*(1-O90)*O90*F90
B91: 7 | C91: 4.6 | D91: 3.4 | E91: 1.4 | F91: 0.3 | G91: 0 | I91: =I90-$K$2*T90 | J91: =J90-$K$2*U90 | K91: =K90-$K$2*V90 | L91: =L90-$K$2*W90 | M91: =M90-$K$2*X90 | N91: =I91+J91*C91+K91*D91+L91*E91+F91*M91 | O91: =1/(1+EXP(-N91)) | P91: =IF(O91>0.5,1,0) | Q91: =O91-G91 | R91: =Q91^2 | S91: =IF(P91=G91,1,0) | T91: =2*(O91-G91)*(1-O91)*O91 | U91: =2*(O91-G91)*(1-O91)*O91*C91 | V91: =2*(O91-G91)*(1-O91)*O91*D91 | W91: =2*(O91-G91)*(1-O91)*O91*E91 | X91: =2*(O91-G91)*(1-O91)*O91*F91
B92: 8 | C92: 5 | D92: 3.4 | E92: 1.5 | F92: 0.2 | G92: 0 | I92: =I91-$K$2*T91 | J92: =J91-$K$2*U91 | K92: =K91-$K$2*V91 | L92: =L91-$K$2*W91 | M92: =M91-$K$2*X91 | N92: =I92+J92*C92+K92*D92+L92*E92+F92*M92 | O92: =1/(1+EXP(-N92)) | P92: =IF(O92>0.5,1,0) | Q92: =O92-G92 | R92: =Q92^2 | S92: =IF(P92=G92,1,0) | T92: =2*(O92-G92)*(1-O92)*O92 | U92: =2*(O92-G92)*(1-O92)*O92*C92 | V92: =2*(O92-G92)*(1-O92)*O92*D92 | W92: =2*(O92-G92)*(1-O92)*O92*E92 | X92: =2*(O92-G92)*(1-O92)*O92*F92
B93: 9 | C93: 4.4 | D93: 2.9 | E93: 1.4 | F93: 0.2 | G93: 0 | I93: =I92-$K$2*T92 | J93: =J92-$K$2*U92 | K93: =K92-$K$2*V92 | L93: =L92-$K$2*W92 | M93: =M92-$K$2*X92 | N93: =I93+J93*C93+K93*D93+L93*E93+F93*M93 | O93: =1/(1+EXP(-N93)) | P93: =IF(O93>0.5,1,0) | Q93: =O93-G93 | R93: =Q93^2 | S93: =IF(P93=G93,1,0) | T93: =2*(O93-G93)*(1-O93)*O93 | U93: =2*(O93-G93)*(1-O93)*O93*C93 | V93: =2*(O93-G93)*(1-O93)*O93*D93 | W93: =2*(O93-G93)*(1-O93)*O93*E93 | X93: =2*(O93-G93)*(1-O93)*O93*F93
B94: 10 | C94: 4.9 | D94: 3.1 | E94: 1.5 | F94: 0.1 | G94: 0 | I94: =I93-$K$2*T93 | J94: =J93-$K$2*U93 | K94: =K93-$K$2*V93 | L94: =L93-$K$2*W93 | M94: =M93-$K$2*X93 | N94: =I94+J94*C94+K94*D94+L94*E94+F94*M94 | O94: =1/(1+EXP(-N94)) | P94: =IF(O94>0.5,1,0) | Q94: =O94-G94 | R94: =Q94^2 | S94: =IF(P94=G94,1,0) | T94: =2*(O94-G94)*(1-O94)*O94 | U94: =2*(O94-G94)*(1-O94)*O94*C94 | V94: =2*(O94-G94)*(1-O94)*O94*D94 | W94: =2*(O94-G94)*(1-O94)*O94*E94 | X94: =2*(O94-G94)*(1-O94)*O94*F94
B95: 11 | C95: 5.4 | D95: 3.7 | E95: 1.5 | F95: 0.2 | G95: 0 | I95: =I94-$K$2*T94 | J95: =J94-$K$2*U94 | K95: =K94-$K$2*V94 | L95: =L94-$K$2*W94 | M95: =M94-$K$2*X94 | N95: =I95+J95*C95+K95*D95+L95*E95+F95*M95 | O95: =1/(1+EXP(-N95)) | P95: =IF(O95>0.5,1,0) | Q95: =O95-G95 | R95: =Q95^2 | S95: =IF(P95=G95,1,0) | T95: =2*(O95-G95)*(1-O95)*O95 | U95: =2*(O95-G95)*(1-O95)*O95*C95 | V95: =2*(O95-G95)*(1-O95)*O95*D95 | W95: =2*(O95-G95)*(1-O95)*O95*E95 | X95: =2*(O95-G95)*(1-O95)*O95*F95
B96: 12 | C96: 4.8 | D96: 3.4 | E96: 1.6 | F96: 0.2 | G96: 0 | I96: =I95-$K$2*T95 | J96: =J95-$K$2*U95 | K96: =K95-$K$2*V95 | L96: =L95-$K$2*W95 | M96: =M95-$K$2*X95 | N96: =I96+J96*C96+K96*D96+L96*E96+F96*M96 | O96: =1/(1+EXP(-N96)) | P96: =IF(O96>0.5,1,0) | Q96: =O96-G96 | R96: =Q96^2 | S96: =IF(P96=G96,1,0) | T96: =2*(O96-G96)*(1-O96)*O96 | U96: =2*(O96-G96)*(1-O96)*O96*C96 | V96: =2*(O96-G96)*(1-O96)*O96*D96 | W96: =2*(O96-G96)*(1-O96)*O96*E96 | X96: =2*(O96-G96)*(1-O96)*O96*F96
B97: 13 | C97: 4.8 | D97: 3 | E97: 1.4 | F97: 0.1 | G97: 0 | I97: =I96-$K$2*T96 | J97: =J96-$K$2*U96 | K97: =K96-$K$2*V96 | L97: =L96-$K$2*W96 | M97: =M96-$K$2*X96 | N97: =I97+J97*C97+K97*D97+L97*E97+F97*M97 | O97: =1/(1+EXP(-N97)) | P97: =IF(O97>0.5,1,0) | Q97: =O97-G97 | R97: =Q97^2 | S97: =IF(P97=G97,1,0) | T97: =2*(O97-G97)*(1-O97)*O97 | U97: =2*(O97-G97)*(1-O97)*O97*C97 | V97: =2*(O97-G97)*(1-O97)*O97*D97 | W97: =2*(O97-G97)*(1-O97)*O97*E97 | X97: =2*(O97-G97)*(1-O97)*O97*F97
... B164: 80 | C164: 5.5 | D164: 2.5 | E164: 4 | F164: 1.3 | G164: 1 | I164: =I163-$K$2*T163 | J164: =J163-$K$2*U163 | K164: =K163-$K$2*V163 | L164: =L163-$K$2*W163 | M164: =M163-$K$2*X163 | N164: =I164+J164*C164+K164*D164+L164*E164+F164*M164 | O164: =1/(1+EXP(-N164)) | P164: =IF(O164>0.5,1,0) | Q164: =O164-G164 | R164: =Q164^2 | S164: =IF(P164=G164,1,0) | T164: =2*(O164-G164)*(1-O164)*O164 | U164: =2*(O164-G164)*(1-O164)*O164*C164 | V164: =2*(O164-G164)*(1-O164)*O164*D164 | W164: =2*(O164-G164)*(1-O164)*O164*E164 | X164: =2*(O164-G164)*(1-O164)*O164*F164
A165: epoch 3 | B165: 1 | C165: 5.1 | D165: 3.5 | E165: 1.4 | F165: 0.2 | G165: 0 | I165: =I164-$K$2*T164 | J165: =J164-$K$2*U164 | K165: =K164-$K$2*V164 | L165: =L164-$K$2*W164 | M165: =M164-$K$2*X164 | N165: =I165+J165*C165+K165*D165+L165*E165+F165*M165 | O165: =1/(1+EXP(-N165)) | P165: =IF(O165>0.5,1,0) | Q165: =O165-G165 | R165: =Q165^2 | S165: =IF(P165=G165,1,0) | T165: =2*(O165-G165)*(1-O165)*O165 | U165: =2*(O165-G165)*(1-O165)*O165*C165 | V165: =2*(O165-G165)*(1-O165)*O165*D165 | W165: =2*(O165-G165)*(1-O165)*O165*E165 | X165: =2*(O165-G165)*(1-O165)*O165*F165
B166: 2 | C166: 4.9 | D166: 3 | E166: 1.4 | F166: 0.2 | G166: 0 | I166: =I165-$K$2*T165 | J166: =J165-$K$2*U165 | K166: =K165-$K$2*V165 | L166: =L165-$K$2*W165 | M166: =M165-$K$2*X165 | N166: =I166+J166*C166+K166*D166+L166*E166+F166*M166 | O166: =1/(1+EXP(-N166)) | P166: =IF(O166>0.5,1,0) | Q166: =O166-G166 | R166: =Q166^2 | S166: =IF(P166=G166,1,0) | T166: =2*(O166-G166)*(1-O166)*O166 | U166: =2*(O166-G166)*(1-O166)*O166*C166 | V166: =2*(O166-G166)*(1-O166)*O166*D166 | W166: =2*(O166-G166)*(1-O166)*O166*E166 | X166: =2*(O166-G166)*(1-O166)*O166*F166
B167: 3 | C167: 4.7 | D167: 3.2 | E167: 1.3 | F167: 0.2 | G167: 0 | I167: =I166-$K$2*T166 | J167: =J166-$K$2*U166 | K167: =K166-$K$2*V166 | L167: =L166-$K$2*W166 | M167: =M166-$K$2*X166 | N167: =I167+J167*C167+K167*D167+L167*E167+F167*M167 | O167: =1/(1+EXP(-N167)) | P167: =IF(O167>0.5,1,0) | Q167: =O167-G167 | R167: =Q167^2 | S167: =IF(P167=G167,1,0) | T167: =2*(O167-G167)*(1-O167)*O167 | U167: =2*(O167-G167)*(1-O167)*O167*C167 | V167: =2*(O167-G167)*(1-O167)*O167*D167 | W167: =2*(O167-G167)*(1-O167)*O167*E167 | X167: =2*(O167-G167)*(1-O167)*O167*F167
...

Sheet SLP-Validation
I2: in validation, bias and teta are obtained from training for each epoch
Z3: REKAP VALIDASI PER EPOCH
G4: Setosa = 0 | I4: Learning Rate | K4: 0.1 | Z4: Epoch | AA4: Loss (MSE) | AB4: Accuracy
G5: Versicolor = 1 | I5: Bobot bias | N5: dot product | O5: Sigmoid | P5: Prediksi | Q5: error | R5: Sum Square Error | S5: Benar? | Z5: 1 | AA5: =AVERAGE(R7:R26) | AB5: =AVERAGE(S7:S26)
A6: EPOCH | B6: No | C6: X1 | D6: X2 | E6: X3 | F6: X4 | G6: TARGET | I6: bias | J6: teta1 | K6: teta2 | L6: teta 3 | M6: teta4 | N6: z | O6: g(z) | S6: benar | Z6: 2 | AA6: =AVERAGE(R27:R46) | AB6: =AVERAGE(S27:S46)
A7: epoch 1 | B7: 1 | C7: 5 | D7: 3.5 | E7: 1.3 | F7: 0.3 | G7: 0 | I7: ='SLP-Training'!$AC$5 | J7: ='SLP-Training'!$AD$5 | K7: ='SLP-Training'!$AE$5 | L7: ='SLP-Training'!$AF$5 | M7: ='SLP-Training'!$AG$5 | N7: =I7+J7*C7+K7*D7+L7*E7+F7*M7 | O7: =1/(1+EXP(-N7)) | P7: =IF(O7>0.5,1,0) | Q7: =O7-G7 | R7: =Q7^2 | S7: =IF(P7=G7,1,0) | Z7: 3 | AA7: =AVERAGE(R47:R66) | AB7: =AVERAGE(S47:S66)
B8: 2 | C8: 4.5 | D8: 2.3 | E8: 1.3 | F8: 0.3 | G8: 0 | I8: =I7 | J8: =J7 | K8: =K7 | L8: =L7 | M8: =M7 | N8: =I8+J8*C8+K8*D8+L8*E8+F8*M8 | O8: =1/(1+EXP(-N8)) | P8: =IF(O8>0.5,1,0) | Q8: =O8-G8 | R8: =Q8^2 | S8: =IF(P8=G8,1,0) | Z8: 4 | AA8: =AVERAGE(R67:R86) | AB8: =AVERAGE(S67:S86)
B9: 3 | C9: 4.4 | D9: 3.2 | E9: 1.3 | F9: 0.2 | G9: 0 | I9: =I8 | J9: =J8 | K9: =K8 | L9: =L8 | M9: =M8 | N9: =I9+J9*C9+K9*D9+L9*E9+F9*M9 | O9: =1/(1+EXP(-N9)) | P9: =IF(O9>0.5,1,0) | Q9: =O9-G9 | R9: =Q9^2 | S9: =IF(P9=G9,1,0) | Z9: 5 | AA9: =AVERAGE(R87:R106) | AB9: =AVERAGE(S87:S106)
B10: 4 | C10: 5 | D10: 3.5 | E10: 1.6 | F10: 0.6 | G10: 0 | I10: =I9 | J10: =J9 | K10: =K9 | L10: =L9 | M10: =M9 | N10: =I10+J10*C10+K10*D10+L10*E10+F10*M10 | O10: =1/(1+EXP(-N10)) | P10: =IF(O10>0.5,1,0) | Q10: =O10-G10 | R10: =Q10^2 | S10: =IF(P10=G10,1,0)
B11: 5 | C11: 5.1 | D11: 3.8 | E11: 1.9 | F11: 0.4 | G11: 0 | I11: =I10 | J11: =J10 | K11: =K10 | L11: =L10 | M11: =M10 | N11: =I11+J11*C11+K11*D11+L11*E11+F11*M11 | O11: =1/(1+EXP(-N11)) | P11: =IF(O11>0.5,1,0) | Q11: =O11-G11 | R11: =Q11^2 | S11: =IF(P11=G11,1,0)
B12: 6 | C12: 4.8 | D12: 3 | E12: 1.4 | F12: 0.3 | G12: 0 | I12: =I11 | J12: =J11 | K12: =K11 | L12: =L11 | M12: =M11 | N12: =I12+J12*C12+K12*D12+L12*E12+F12*M12 | O12: =1/(1+EXP(-N12)) | P12: =IF(O12>0.5,1,0) | Q12: =O12-G12 | R12: =Q12^2 | S12: =IF(P12=G12,1,0)
B13: 7 | C13: 5.1 | D13: 3.8 | E13: 1.6 | F13: 0.2 | G13: 0 | I13: =I12 | J13: =J12 | K13: =K12 | L13: =L12 | M13: =M12 | N13: =I13+J13*C13+K13*D13+L13*E13+F13*M13 | O13: =1/(1+EXP(-N13)) | P13: =IF(O13>0.5,1,0) | Q13: =O13-G13 | R13: =Q13^2 | S13: =IF(P13=G13,1,0)
B14: 8 | C14: 4.6 | D14: 3.2 | E14: 1.4 | F14: 0.2 | G14: 0 | I14: =I13 | J14: =J13 | K14: =K13 | L14: =L13 | M14: =M13 | N14: =I14+J14*C14+K14*D14+L14*E14+F14*M14 | O14: =1/(1+EXP(-N14)) | P14: =IF(O14>0.5,1,0) | Q14: =O14-G14 | R14: =Q14^2 | S14: =IF(P14=G14,1,0)
B15: 9 | C15: 5.3 | D15: 3.7 | E15: 1.5 | F15: 0.2 | G15: 0 | I15: =I14 | J15: =J14 | K15: =K14 | L15: =L14 | M15: =M14 | N15: =I15+J15*C15+K15*D15+L15*E15+F15*M15 | O15: =1/(1+EXP(-N15)) | P15: =IF(O15>0.5,1,0) | Q15: =O15-G15 | R15: =Q15^2 | S15: =IF(P15=G15,1,0)
B16: 10 | C16: 5 | D16: 3.3 | E16: 1.4 | F16: 0.2 | G16: 0 | I16: =I15 | J16: =J15 | K16: =K15 | L16: =L15 | M16: =M15 | N16: =I16+J16*C16+K16*D16+L16*E16+F16*M16 | O16: =1/(1+EXP(-N16)) | P16: =IF(O16>0.5,1,0) | Q16: =O16-G16 | R16: =Q16^2 | S16: =IF(P16=G16,1,0)
B17: 11 | C17: 5.5 | D17: 2.6 | E17: 4.4 | F17: 1.2 | G17: 1 | I17: =I16 | J17: =J16 | K17: =K16 | L17: =L16 | M17: =M16 | N17: =I17+J17*C17+K17*D17+L17*E17+F17*M17 | O17: =1/(1+EXP(-N17)) | P17: =IF(O17>0.5,1,0) | Q17: =O17-G17 | R17: =Q17^2 | S17: =IF(P17=G17,1,0)
B18: 12 | C18: 6.1 | D18: 3 | E18: 4.6 | F18: 1.4 | G18: 1 | I18: =I17 | J18: =J17 | K18: =K17 | L18: =L17 | M18: =M17 | N18: =I18+J18*C18+K18*D18+L18*E18+F18*M18 | O18: =1/(1+EXP(-N18)) | P18: =IF(O18>0.5,1,0) | Q18: =O18-G18 | R18: =Q18^2 | S18: =IF(P18=G18,1,0)
B19: 13 | C19: 5.8 | D19: 2.6 | E19: 4 | F19: 1.2 | G19: 1 | I19: =I18 | J19: =J18 | K19: =K18 | L19: =L18 | M19: =M18 | N19: =I19+J19*C19+K19*D19+L19*E19+F19*M19 | O19: =1/(1+EXP(-N19)) | P19: =IF(O19>0.5,1,0) | Q19: =O19-G19 | R19: =Q19^2 | S19: =IF(P19=G19,1,0)
B20: 14 | C20: 5 | D20: 2.3 | E20: 3.3 | F20: 1 | G20: 1 | I20: =I19 | J20: =J19 | K20: =K19 | L20: =L19 | M20: =M19 | N20: =I20+J20*C20+K20*D20+L20*E20+F20*M20 | O20: =1/(1+EXP(-N20)) | P20: =IF(O20>0.5,1,0) | Q20: =O20-G20 | R20: =Q20^2 | S20: =IF(P20=G20,1,0)
B21: 15 | C21: 5.6 | D21: 2.7 | E21: 4.2 | F21: 1.3 | G21: 1 | I21: =I20 | J21: =J20 | K21: =K20 | L21: =L20 | M21: =M20 | N21: =I21+J21*C21+K21*D21+L21*E21+F21*M21 | O21: =1/(1+EXP(-N21)) | P21: =IF(O21>0.5,1,0) | Q21: =O21-G21 | R21: =Q21^2 | S21: =IF(P21=G21,1,0)
... B26: 20 | C26: 5.7 | D26: 2.8 | E26: 4.1 | F26: 1.3 | G26: 1 | I26: =I25 | J26: =J25 | K26: =K25 | L26: =L25 | M26: =M25 | N26: =I26+J26*C26+K26*D26+L26*E26+F26*M26 | O26: =1/(1+EXP(-N26)) | P26: =IF(O26>0.5,1,0) | Q26: =O26-G26 | R26: =Q26^2 | S26: =IF(P26=G26,1,0)
A27: epoch 2 | B27: 1 | C27: 5 | D27: 3.5 | E27: 1.3 | F27: 0.3 | G27: 0 | I27: ='SLP-Training'!$AC$6 | J27: ='SLP-Training'!$AD$6 | K27: ='SLP-Training'!$AE$6 | L27: ='SLP-Training'!$AF$6 | M27: ='SLP-Training'!$AG$6 | N27: =I27+J27*C27+K27*D27+L27*E27+F27*M27 | O27: =1/(1+EXP(-N27)) | P27: =IF(O27>0.5,1,0) | Q27: =O27-G27 | R27: =Q27^2 | S27: =IF(P27=G27,1,0)
B28: 2 | C28: 4.5 | D28: 2.3 | E28: 1.3 | F28: 0.3 | G28: 0 | I28: =I27 | J28: =J27 | K28: =K27 | L28: =L27 | M28: =M27 | N28: =I28+J28*C28+K28*D28+L28*E28+F28*M28 | O28: =1/(1+EXP(-N28)) | P28: =IF(O28>0.5,1,0) | Q28: =O28-G28 | R28: =Q28^2 | S28: =IF(P28=G28,1,0)
B29: 3 | C29: 4.4 | D29: 3.2 | E29: 1.3 | F29: 0.2 | G29: 0 | I29: =I28 | J29: =J28 | K29: =K28 | L29: =L28 | M29: =M28 | N29: =I29+J29*C29+K29*D29+L29*E29+F29*M29 | O29: =1/(1+EXP(-N29)) | P29: =IF(O29>0.5,1,0) | Q29: =O29-G29 | R29: =Q29^2 | S29: =IF(P29=G29,1,0)
B30: 4 | C30: 5 | D30: 3.5 | E30: 1.6 | F30: 0.6 | G30: 0 | I30: =I29 | J30: =J29 | K30: =K29 | L30: =L29 | M30: =M29 | N30: =I30+J30*C30+K30*D30+L30*E30+F30*M30 | O30: =1/(1+EXP(-N30)) | P30: =IF(O30>0.5,1,0) | Q30: =O30-G30 | R30: =Q30^2 | S30: =IF(P30=G30,1,0)
B31: 5 | C31: 5.1 | D31: 3.8 | E31: 1.9 | F31: 0.4 | G31: 0 | I31: =I30 | J31: =J30 | K31: =K30 | L31: =L30 | M31: =M30 | N31: =I31+J31*C31+K31*D31+L31*E31+F31*M31 | O31: =1/(1+EXP(-N31)) | P31: =IF(O31>0.5,1,0) | Q31: =O31-G31 | R31: =Q31^2 | S31: =IF(P31=G31,1,0)
B32: 6 | C32: 4.8 | D32: 3 | E32: 1.4 | F32: 0.3 | G32: 0 | I32: =I31 | J32: =J31 | K32: =K31 | L32: =L31 | M32: =M31 | N32: =I32+J32*C32+K32*D32+L32*E32+F32*M32 | O32: =1/(1+EXP(-N32)) | P32: =IF(O32>0.5,1,0) | Q32: =O32-G32 | R32: =Q32^2 | S32: =IF(P32=G32,1,0)
B33: 7 | C33: 5.1 | D33: 3.8 | E33: 1.6 | F33: 0.2 | G33: 0 | I33: =I32 | J33: =J32 | K33: =K32 | L33: =L32 | M33: =M32 | N33: =I33+J33*C33+K33*D33+L33*E33+F33*M33 | O33: =1/(1+EXP(-N33)) | P33: =IF(O33>0.5,1,0) | Q33: =O33-G33 | R33: =Q33^2 | S33: =IF(P33=G33,1,0)
B34: 8 | C34: 4.6 | D34: 3.2 | E34: 1.4 | F34: 0.2 | G34: 0 | I34: =I33 | J34: =J33 | K34: =K33 | L34: =L33 | M34: =M33 | N34: =I34+J34*C34+K34*D34+L34*E34+F34*M34 | O34: =1/(1+EXP(-N34)) | P34: =IF(O34>0.5,1,0) | Q34: =O34-G34 | R34: =Q34^2 | S34: =IF(P34=G34,1,0)
B35: 9 | C35: 5.3 | D35: 3.7 | E35: 1.5 | F35: 0.2 | G35: 0 | I35: =I34 | J35: =J34 | K35: =K34 | L35: =L34 | M35: =M34 | N35: =I35+J35*C35+K35*D35+L35*E35+F35*M35 | O35: =1/(1+EXP(-N35)) | P35: =IF(O35>0.5,1,0) | Q35: =O35-G35 | R35: =Q35^2 | S35: =IF(P35=G35,1,0)
B36: 10 | C36: 5 | D36: 3.3 | E36: 1.4 | F36: 0.2 | G36: 0 | I36: =I35 | J36: =J35 | K36: =K35 | L36: =L35 | M36: =M35 | N36: =I36+J36*C36+K36*D36+L36*E36+F36*M36 | O36: =1/(1+EXP(-N36)) | P36: =IF(O36>0.5,1,0) | Q36: =O36-G36 | R36: =Q36^2 | S36: =IF(P36=G36,1,0)
B37: 11 | C37: 5.5 | D37: 2.6 | E37: 4.4 | F37: 1.2 | G37: 1 | I37: =I36 | J37: =J36 | K37: =K36 | L37: =L36 | M37: =M36 | N37: =I37+J37*C37+K37*D37+L37*E37+F37*M37 | O37: =1/(1+EXP(-N37)) | P37: =IF(O37>0.5,1,0) | Q37: =O37-G37 | R37: =Q37^2 | S37: =IF(P37=G37,1,0)
B38: 12 | C38: 6.1 | D38: 3 | E38: 4.6 | F38: 1.4 | G38: 1 | I38: =I37 | J38: =J37 | K38: =K37 | L38: =L37 | M38: =M37 | N38: =I38+J38*C38+K38*D38+L38*E38+F38*M38 | O38: =1/(1+EXP(-N38)) | P38: =IF(O38>0.5,1,0) | Q38: =O38-G38 | R38: =Q38^2 | S38: =IF(P38=G38,1,0)
B39: 13 | C39: 5.8 | D39: 2.6 | E39: 4 | F39: 1.2 | G39: 1 | I39: =I38 | J39: =J38 | K39: =K38 | L39: =L38 | M39: =M38 | N39: =I39+J39*C39+K39*D39+L39*E39+F39*M39 | O39: =1/(1+EXP(-N39)) | P39: =IF(O39>0.5,1,0) | Q39: =O39-G39 | R39: =Q39^2 | S39: =IF(P39=G39,1,0)
... B46: 20 | C46: 5.7 | D46: 2.8 | E46: 4.1 | F46: 1.3 | G46: 1 | I46: =I45 | J46: =J45 | K46: =K45 | L46: =L45 | M46: =M45 | N46: =I46+J46*C46+K46*D46+L46*E46+F46*M46 | O46: =1/(1+EXP(-N46)) | P46: =IF(O46>0.5,1,0) | Q46: =O46-G46 | R46: =Q46^2 | S46: =IF(P46=G46,1,0)
A47: epoch 3 | B47: 1 | C47: 5 | D47: 3.5 | E47: 1.3 | F47: 0.3 | G47: 0 | I47: ='SLP-Training'!$AC$7 | J47: ='SLP-Training'!$AD$7 | K47: ='SLP-Training'!$AE$7 | L47: ='SLP-Training'!$AF$7 | M47: ='SLP-Training'!$AG$7 | N47: =I47+J47*C47+K47*D47+L47*E47+F47*M47 | O47: =1/(1+EXP(-N47)) | P47: =IF(O47>0.5,1,0) | Q47: =O47-G47 | R47: =Q47^2 | S47: =IF(P47=G47,1,0)
B48: 2 | C48: 4.5 | D48: 2.3 | E48: 1.3 | F48: 0.3 | G48: 0 | I48: =I47 | J48: =J47 | K48: =K47 | L48: =L47 | M48: =M47 | N48: =I48+J48*C48+K48*D48+L48*E48+F48*M48 | O48: =1/(1+EXP(-N48)) | P48: =IF(O48>0.5,1,0) | Q48: =O48-G48 | R48: =Q48^2 | S48: =IF(P48=G48,1,0)
B49: 3 | C49: 4.4 | D49: 3.2 | E49: 1.3 | F49: 0.2 | G49: 0 | I49: =I48 | J49: =J48 | K49: =K48 | L49: =L48 | M49: =M48 | N49: =I49+J49*C49+K49*D49+L49*E49+F49*M49 | O49: =1/(1+EXP(-N49)) | P49: =IF(O49>0.5,1,0) | Q49: =O49-G49 | R49: =Q49^2 | S49: =IF(P49=G49,1,0)
B50: 4 | C50: 5 | D50: 3.5 | E50: 1.6 | F50: 0.6 | G50: 0 | I50: =I49 | J50: =J49 | K50: =K49 | L50: =L49 | M50: =M49 | N50: =I50+J50*C50+K50*D50+L50*E50+F50*M50 | O50: =1/(1+EXP(-N50)) | P50: =IF(O50>0.5,1,0) | Q50: =O50-G50 | R50: =Q50^2 | S50: =IF(P50=G50,1,0)
B51: 5 | C51: 5.1 | D51: 3.8 | E51: 1.9 | F51: 0.4 | G51: 0 | I51: =I50 | J51: =J50 | K51: =K50 | L51: =L50 | M51: =M50 | N51: =I51+J51*C51+K51*D51+L51*E51+F51*M51 | O51: =1/(1+EXP(-N51)) | P51: =IF(O51>0.5,1,0) | Q51: =O51-G51 | R51: =Q51^2 | S51: =IF(P51=G51,1,0)
...

Sheet Charts
A1: SLP Iris - Setosa (0) vs Versicolor (1)
A2: Learning rate = 0.1 | Epoch = 5 | Bobot awal = 0.5
A3: Training = 80 sampel | Validation = 20 sampel
A5: Epoch | B5: Train Accuracy | C5: Validation Accuracy | D5: Train Loss | E5: Validation Loss
A6: 1 | B6: ='SLP-Training'!AB5 | C6: ='SLP-Validation'!AB5 | D6: ='SLP-Training'!AA5 | E6: ='SLP-Validation'!AA5
A7: 2 | B7: ='SLP-Training'!AB6 | C7: ='SLP-Validation'!AB6 | D7: ='SLP-Training'!AA6 | E7: ='SLP-Validation'!AA6
A8: 3 | B8: ='SLP-Training'!AB7 | C8: ='SLP-Validation'!AB7 | D8: ='SLP-Training'!AA7 | E8: ='SLP-Validation'!AA7
A9: 4 | B9: ='SLP-Training'!AB8 | C9: ='SLP-Validation'!AB8 | D9: ='SLP-Training'!AA8 | E9: ='SLP-Validation'!AA8
A10: 5 | B10: ='SLP-Training'!AB9 | C10: ='SLP-Validation'!AB9 | D10: ='SLP-Training'!AA9 | E10: ='SLP-Validation'!AA9
